Workbook

Sheet Summary
A1: MBPay (FoxPro) → HRSys (.NET) Migration Map
A2: Source: MBPay 2026.10.27.zip vs. HRReport repo, analyzed 2026-10-27.
A3: Key finding: MBPay uses the same MySQL schemas (pay, pis/secpis) as HRSys, so this is feature porting, not data migration.
A5: Module | B5: Total | C5: Has page | D5: Partial | E5: Missing | F5: Verify | G5: % Covered
A6: System | B6: =COUNTIF('Feature Map'!$A:$A,$A6) -> 4 | C6: =COUNTIFS('Feature Map'!$A:$A,$A6,'Feature Map'!$E:$E,"Has page") -> 2 | D6: =COUNTIFS('Feature Map'!$A:$A,$A6,'Feature Map'!$E:$E,"Partial") -> 1 | E6: =COUNTIFS('Feature Map'!$A:$A,$A6,'Feature Map'!$E:$E,"Missing") -> 1 | F6: =COUNTIFS('Feature Map'!$A:$A,$A6,'Feature Map'!$E:$E,"Verify") -> 0 | G6: =IF(B6=0,0,C6/B6) -> 0.5
A7: Setup | B7: =COUNTIF('Feature Map'!$A:$A,$A7) -> 15 | C7: =COUNTIFS('Feature Map'!$A:$A,$A7,'Feature Map'!$E:$E,"Has page") -> 5 | D7: =COUNTIFS('Feature Map'!$A:$A,$A7,'Feature Map'!$E:$E,"Partial") -> 3 | E7: =COUNTIFS('Feature Map'!$A:$A,$A7,'Feature Map'!$E:$E,"Missing") -> 7 | F7: =COUNTIFS('Feature Map'!$A:$A,$A7,'Feature Map'!$E:$E,"Verify") -> 0 | G7: =IF(B7=0,0,C7/B7) -> 0.33333333
A8: Transaction | B8: =COUNTIF('Feature Map'!$A:$A,$A8) -> 13 | C8: =COUNTIFS('Feature Map'!$A:$A,$A8,'Feature Map'!$E:$E,"Has page") -> 4 | D8: =COUNTIFS('Feature Map'!$A:$A,$A8,'Feature Map'!$E:$E,"Partial") -> 3 | E8: =COUNTIFS('Feature Map'!$A:$A,$A8,'Feature Map'!$E:$E,"Missing") -> 6 | F8: =COUNTIFS('Feature Map'!$A:$A,$A8,'Feature Map'!$E:$E,"Verify") -> 0 | G8: =IF(B8=0,0,C8/B8) -> 0.30769231
A9: Reports | B9: =COUNTIF('Feature Map'!$A:$A,$A9) -> 46 | C9: =COUNTIFS('Feature Map'!$A:$A,$A9,'Feature Map'!$E:$E,"Has page") -> 20 | D9: =COUNTIFS('Feature Map'!$A:$A,$A9,'Feature Map'!$E:$E,"Partial") -> 6 | E9: =COUNTIFS('Feature Map'!$A:$A,$A9,'Feature Map'!$E:$E,"Missing") -> 20 | F9: =COUNTIFS('Feature Map'!$A:$A,$A9,'Feature Map'!$E:$E,"Verify") -> 0 | G9: =IF(B9=0,0,C9/B9) -> 0.43478261
A10: Account Configuration | B10: =COUNTIF('Feature Map'!$A:$A,$A10) -> 12 | C10: =COUNTIFS('Feature Map'!$A:$A,$A10,'Feature Map'!$E:$E,"Has page") -> 0 | D10: =COUNTIFS('Feature Map'!$A:$A,$A10,'Feature Map'!$E:$E,"Partial") -> 1 | E10: =COUNTIFS('Feature Map'!$A:$A,$A10,'Feature Map'!$E:$E,"Missing") -> 11 | F10: =COUNTIFS('Feature Map'!$A:$A,$A10,'Feature Map'!$E:$E,"Verify") -> 0 | G10: =IF(B10=0,0,C10/B10) -> 0
A11: Computation | B11: =COUNTIF('Feature Map'!$A:$A,$A11) -> 11 | C11: =COUNTIFS('Feature Map'!$A:$A,$A11,'Feature Map'!$E:$E,"Has page") -> 0 | D11: =COUNTIFS('Feature Map'!$A:$A,$A11,'Feature Map'!$E:$E,"Partial") -> 7 | E11: =COUNTIFS('Feature Map'!$A:$A,$A11,'Feature Map'!$E:$E,"Missing") -> 3 | F11: =COUNTIFS('Feature Map'!$A:$A,$A11,'Feature Map'!$E:$E,"Verify") -> 1 | G11: =IF(B11=0,0,C11/B11) -> 0
A12: Total | B12: =SUM(B6:B11) -> 101 | C12: =SUM(C6:C11) -> 31 | D12: =SUM(D6:D11) -> 21 | E12: =SUM(E6:E11) -> 48 | F12: =SUM(F6:F11) -> 1 | G12: =IF(B12=0,0,C12/B12) -> 0.30693069
A14: % Covered = rows with an HRSys page of the same name. The logic still has to be checked against FoxPro.
A16: Phase 1 Findings by Severity | B16: Total | C16: Open
A17: Critical | B17: =COUNTIF('Phase 1 Findings'!$F:$F,A17) -> 3 | C17: =COUNTIFS('Phase 1 Findings'!$F:$F,A17,'Phase 1 Findings'!$G:$G,"Open") -> 1
A18: High | B18: =COUNTIF('Phase 1 Findings'!$F:$F,A18) -> 10 | C18: =COUNTIFS('Phase 1 Findings'!$F:$F,A18,'Phase 1 Findings'!$G:$G,"Open") -> 1
A19: Medium | B19: =COUNTIF('Phase 1 Findings'!$F:$F,A19) -> 7 | C19: =COUNTIFS('Phase 1 Findings'!$F:$F,A19,'Phase 1 Findings'!$G:$G,"Open") -> 0
A20: Low | B20: =COUNTIF('Phase 1 Findings'!$F:$F,A20) -> 2 | C20: =COUNTIFS('Phase 1 Findings'!$F:$F,A20,'Phase 1 Findings'!$G:$G,"Open") -> 1

Sheet Feature Map
A1: Module | B1: FoxPro Menu / Function | C1: FoxPro Form / Program | D1: HRSys Equivalent | E1: Status | F1: Notes | G1: Phase | H1: Remarks
A2: System | B2: User Administration | C2: FRMUSERMGR | D2: _0506_UserManagement | E2: Has page | G2: 6
A3: System | B3: Change Password | C3: FRMCHANGEPASS | D3: login module | E3: Partial | F3: verify | G3: 6
A4: System | B4: Log-out / Exit | C4: LOGIN | E4: Has page | F4: web login | G4: 6
A5: System | B5: Menu/access per user | C5: pay.sysmenu, pay.useraccess, pay.acctaccess, pay.reportaccess | E5: Missing | G5: 6
A6: Setup | B6: Employee Rate | C6: FRMEMPRATES | D6: _0505_EmployeeRates | E6: Has page | G6: 2
A7: Setup | B7: Surety Bond Quota | C7: FRMSBQUOTA | E7: Missing | G7: 2
A8: Setup | B8: SSS Table | C8: FRMSSSTABLE | D8: _0502_05_SSS | E8: Has page | G8: 2
A9: Setup | B9: Phil-Health Table | C9: FRMPHICTABLE | D9: _0502_06_PHIC | E9: Has page | G9: 2
A10: Setup | B10: Rate Over Basic Pay | C10: FRMOTSETUP | D10: _0504_00_PayrollgrpRates | E10: Partial | G10: 2
A11: Setup | B11: Salary Grade | C11: salaryGrade | E11: Missing | G11: 2
A12: Setup | B12: Accounts Entry | C12: FRMCHAROFACCT | D12: _0502_ChartOfAccounts | E12: Has page | G12: 2
A13: Setup | B13: Account Mapping | C13: AcctMapping | E13: Missing | G13: 2
A14: Setup | B14: Payroll Content | C14: PAYCONTENT | E14: Missing | G14: 2
A15: Setup | B15: Deduction Order Setup | C15: DEDUCTIONORDER | E15: Missing | G15: 2
A16: Setup | B16: Annual Tax Matrix | C16: TAX_MATRIX | D16: _0502_04_Tax | E16: Has page | G16: 2
A17: Setup | B17: Semi-Monthly Tax Matrix | C17: FRMSEMIMONTHLYTAX | D17: _0502_04_Tax | E17: Partial | F17: verify | G17: 2
A18: Setup | B18: Account Code Entry | C18: FRMACCTCODE | D18: Chart of Accounts | E18: Partial | G18: 2
A19: Setup | B19: Minimum Rate Setup | C19: FRMMINIMUMSETUP | E19: Missing | G19: 2
A20: Setup | B20: Status visible in payroll | C20: emp_status_visible_to_pay | E20: Missing | G20: 2
A21: Transaction | B21: Earnings (per employee) | C21: FRMEARNFINAL | D21: _0602_EarningsEntry | E21: Has page | G21: 3
A22: Transaction | B22: Earnings (group) | C22: FRMEARNINGS | D22: _0602_12_GroupEarnings | E22: Has page | G22: 3
A23: Transaction | B23: Fixed Earnings / Grp Fixed Earnings | C23: fixed_earnings, fixed_earnings_grp | D23: _0602_11_FixedEarnings | E23: Has page | G23: 3
A24: Transaction | B24: 13th Mo Salary deduction setter | C24: frm13thMonth_ded_Setter | E24: Missing | G24: 3
A25: Transaction | B25: Deductions (per employee) | C25: FRMCANCELDEDN | D25: _0604_DeductionEntry | E25: Has page | G25: 3
A26: Transaction | B26: Deductions (group) | C26: FRMDEDUCTIONS | D26: _0604_DeductionEntry | E26: Partial | G26: 3
A27: Transaction | B27: Partial Deductions | C27: FRMPARTIALDED | E27: Missing | G27: 3
A28: Transaction | B28: Mandatory Deduction | C28: ded_mandatory | D28: DedmandatoryDataAccess | E28: Partial | G28: 3
A29: Transaction | B29: Hospitalization | C29: ded_hospitalization | E29: Missing | G29: 3
A30: Transaction | B30: Payroll | C30: PAYROLL4 (largest form, ~400KB) | D30: _0605/_0606_PayrollProcess, DA605DataAccess | E30: Partial | F30: core — see Phase 1 | G30: 3
A31: Transaction | B31: Payroll variants | C31: payroll4_manual, _negativepay, _below500, _40_prcnt_salary, _calculator, _13mogenerator, retro_pay | E31: Missing | G31: 3
A32: Transaction | B32: Payroll (custom) | C32: PAYROLLX | E32: Missing | G32: 3
A33: Transaction | B33: BIR Fields Mapping / Data Migration / Excel Upload | C33: bir_fields_mapping, bir_empmas_migration, bir_excelUploading | E33: Missing | G33: 3
A34: Reports | B34: Deductions Summary | C34: FRMDEDSUM | D34: _1152_DeductionSummary | E34: Has page | G34: 5
A35: Reports | B35: Earnings Summary | C35: FRMEARNSUM | D35: _1102_EarningsSummary | E35: Has page | G35: 5
A36: Reports | B36: Deductions History | C36: FRMDEDSUMEMP | D36: _1154_DeductionHistory | E36: Has page | G36: 5
A37: Reports | B37: Earnings History | C37: FRMEARNSUMEMP | D37: _1103_EarningsHistory | E37: Has page | G37: 5
A38: Reports | B38: Monthly Deductions | C38: FRMDEDMONTHLY | D38: _1155_MonthlyDeductionSummary | E38: Has page | G38: 5
A39: Reports | B39: Monthly Earnings | C39: FRMEARNMONTHLY | D39: _1104_MonthlyEarningsReport | E39: Has page | G39: 5
A40: Reports | B40: Loan Summary | C40: loans_management | D40: _0603_LoansManagement | E40: Partial | G40: 5
...

Sheet Unmapped Tables
A1: Schema | B1: Table | C1: HRSys Status | D1: Remarks
A2: pay | B2: 13thmogrp | C2: Not referenced in code
A3: pay | B3: 13thmosched | C3: Not referenced in code
A4: pay | B4: 13thmosettings | C4: Not referenced in code
A5: pay | B5: acctaccess | C5: Not referenced in code
A6: pay | B6: acctconfig | C6: Not referenced in code
A7: pay | B7: allowanceperday | C7: Not referenced in code
A8: pay | B8: audit_payroll_lock | C8: Not referenced in code
A9: pay | B9: coaconfig | C9: Not referenced in code
A10: pay | B10: dedmandatory_trans | C10: Not referenced in code
A11: pay | B11: deductiondressing | C11: Not referenced in code
A12: pay | B12: empdedexemption | C12: Not referenced in code
A13: pay | B13: empstatpisval | C13: Not referenced in code
... A51: pis | B51: userclientaccess | C51: Not referenced in code

Sheet Phases
A1: Phase | B1: Scope | C1: Features | D1: Missing | E1: Partial / Verify
A2: 1 | B2: Payroll computation parity: compare `payroll4.SCT` + `PROGS` with `DA605DataAccess`, run both on the same period, and fix differences. Add tests in `HRApiLibrary.Tests`. | C2: =COUNTIF('Feature Map'!$G:$G,A2) -> 11 | D2: =COUNTIFS('Feature Map'!$G:$G,A2,'Feature Map'!$E:$E,"Missing") -> 3 | E2: =COUNTIFS('Feature Map'!$G:$G,A2,'Feature Map'!$E:$E,"Partial")+COUNTIFS('Feature Map'!$G:$G,A2,'Feature Map'!$E:$E,"Verify") -> 8
A3: 2 | B3: Missing account configs that affect computation: OT, minimum net, ECOLA/CTPA/SEA, meal/uniform/retirement, deduction order, employee status inclusion, tax setter, 13th month settings. | C3: =COUNTIF('Feature Map'!$G:$G,A3) -> 27 | D3: =COUNTIFS('Feature Map'!$G:$G,A3,'Feature Map'!$E:$E,"Missing") -> 18 | E3: =COUNTIFS('Feature Map'!$G:$G,A3,'Feature Map'!$E:$E,"Partial")+COUNTIFS('Feature Map'!$G:$G,A3,'Feature Map'!$E:$E,"Verify") -> 4
A4: 3 | B4: Missing transactions: partial deductions, hospitalization, retro pay, payroll variants, BIR upload. | C4: =COUNTIF('Feature Map'!$G:$G,A4) -> 13 | D4: =COUNTIFS('Feature Map'!$G:$G,A4,'Feature Map'!$E:$E,"Missing") -> 6 | E4: =COUNTIFS('Feature Map'!$G:$G,A4,'Feature Map'!$E:$E,"Partial")+COUNTIFS('Feature Map'!$G:$G,A4,'Feature Map'!$E:$E,"Verify") -> 3
A5: 4 | B5: Government reports and files: SSS R1-A, PhilHealth ER2/text file, bank text file, Alphalist, BIR 1700/2316. | C5: =COUNTIF('Feature Map'!$G:$G,A5) -> 13 | D5: =COUNTIFS('Feature Map'!$G:$G,A5,'Feature Map'!$E:$E,"Missing") -> 10 | E5: =COUNTIFS('Feature Map'!$G:$G,A5,'Feature Map'!$E:$E,"Partial")+COUNTIFS('Feature Map'!$G:$G,A5,'Feature Map'!$E:$E,"Verify") -> 3
A6: 5 | B6: Remaining report variants: Gov / per client / per employee / dressed / 2-liner, COE, balance report. | C6: =COUNTIF('Feature Map'!$G:$G,A6) -> 33 | D6: =COUNTIFS('Feature Map'!$G:$G,A6,'Feature Map'!$E:$E,"Missing") -> 10 | E6: =COUNTIFS('Feature Map'!$G:$G,A6,'Feature Map'!$E:$E,"Partial")+COUNTIFS('Feature Map'!$G:$G,A6,'Feature Map'!$E:$E,"Verify") -> 3
A7: 6 | B7: Access control and archiving: sysmenu/useraccess equivalents, record archiver. | C7: =COUNTIF('Feature Map'!$G:$G,A7) -> 4 | D7: =COUNTIFS('Feature Map'!$G:$G,A7,'Feature Map'!$E:$E,"Missing") -> 1 | E7: =COUNTIFS('Feature Map'!$G:$G,A7,'Feature Map'!$E:$E,"Partial")+COUNTIFS('Feature Map'!$G:$G,A7,'Feature Map'!$E:$E,"Verify") -> 1
A9: Counts come from the Phase column (G) in Feature Map. Edit column G to re-plan.

Sheet Phase 1 Findings
A1: # | B1: Area | C1: FoxPro (payroll4) | D1: HRSys (DA605) | E1: Gap | F1: Severity | G1: Status | H1: Remarks
A2: 1 | B2: Payroll process UI | C2: PAYROLL4 form runs the whole process | D2: /03/0605 page has no content, /03/0606 is a placeholder; nothing in any branch calls DA605DataAccess | E2: The .NET payroll process cannot be run by users | F2: Critical | G2: Open | H2: Next: payroll process UI on /03/0605
A3: 2 | B3: Basic pay | C3: rateid 1 (monthly) = rate/2; 2 (daily) = rate × days; 3 (semi-monthly) = rate; employee rate 0 → client rate × days; monthly/semi-monthly paid even with 0 days | D3: No rule in backend; Amount is whatever the UI sends to _03TmpTbltran | E3: Basic pay rules missing | F3: High | G3: In progress | H3: PayrollCalculator.BasicPay done and tested; wiring waits for the UI
A4: 3 | B4: SSS basis | C4: Bracket uses month-to-date earnings (already saved this month + current); EE = bracket EE − SSS already deducted this month | D4: Bracket uses current TRN earnings only, then subtracts SSS already deducted this month | E4: 2nd cutoff under-deducts SSS | F4: High | G4: Fixed | H4: Month-to-date basis in _01_Premium
A5: 4 | B5: SSS max | C5: isMaxSSS = 1 → highest bracket regardless of earnings | D5: Not supported | E5: Missing | F5: Medium | G5: In progress | H5: Calculator supports IsMaxSss; no column for it in HRSys yet
A6: 5 | B6: SSS ER / ECC | C6: Computes ER share and stores it (used by remittance reports) | D6: EE only | E6: ER share missing | F6: Medium | G6: In progress | H6: Calculator returns ER; no table to store it yet (needed by remittance reports)
A7: 6 | B7: SSS non-member | C7: iswithSSS != 1 → skip | D7: Earnings forced to 0 but still joined to matrix; a bracket starting at 0 would deduct minimum EE | E7: Verify matrixSSS lowest bracket | F7: Medium | G7: Fixed | H7: Non-members get 0
A8: 7 | B8: PhilHealth formula | C8: EE = fixed + (earnings × percent / 100) / 2 | D8: EE = ee + earnings × percent / 100 (no ÷ 2) | E8: Double the percentage part, unless matrixPHIC.percent is already halved — verify | F8: High | G8: Fixed | H8: ÷ 2 applied. Verify that matrixPHIC.percent holds the total rate (e.g. 5), not the EE share
A9: 8 | B9: PhilHealth basis | C9: Month-to-date earnings, minus PHIC already deducted this month; skip if earnings = 0 | D9: Current TRN earnings only | E9: Same as #3 | F9: High | G9: Fixed | H9: Month-to-date basis
A10: 9 | B10: PhilHealth non-member | C10: iswithPHIC != 1 → skip | D10: if(wphic!=1, 0, …) - deducted → negative amount if there were earlier deductions | E10: Wrong sign | F10: Low | G10: Fixed | H10: Never negative
A11: 10 | B11: Pag-IBIG SQL | C11: n/a | D11: left join pagibig p on t.t.Amount between … — MySQL error “Unknown column t.t.Amount” | E11: D004 computation fails at runtime | F11: Critical | G11: Fixed | H11: SQL replaced
A12: 11 | B12: Pag-IBIG rules | C12: iswithPagibig check; month-to-date earnings; EE − already deducted | D12: No wPagibig check; current TRN only; if(deducted > earnings, 0, …) compares premium to earnings | E12: Logic differs | F12: High | G12: Fixed | H12: wPagibig check, month-to-date basis
A13: 12 | B13: Tax basis | C13: Taxable = current-period taxable earnings − SSS − PHIC − Pag-IBIG (current period) | D13: (trn = @Trn or Status = 'P') and AcctNumber in coaTax → includes every posted record of the employee (all history); premiums not deducted | E13: Tax heavily overstated | F13: Critical | G13: Fixed | H13: Current TRN only, minus SSS/PHIC/Pag-IBIG
... A23: 22 | B23: Other earnings | C23: ECOLA, CTPA, SEA, meal allowance, free uniform, incentive leave, provision for retirement, hospitalization, retro pay, 13th month | D23: Not implemented (fixed earnings and mandatory deductions exist) | E23: Missing | F23: High | G23: Open | H23: Phase 2

Sheet Phase 1 Decisions
A1: # | B1: Question | C1: FoxPro actual behavior | D1: Recommendation | E1: Decision
A2: D1 | B2: Negative premiums | C2: IIF(mpremee<1, mpremee=0, …) is a no-op in FoxPro, so negative premiums (refunds) are not clamped | D2: Clamp to 0, which is what the code was meant to do | E2: Approved (2026-10-27)
A3: D2 | B3: Minimum net: government deductions | C3: The filter acct != 'D001' OR acct != 'D002' … is always true, so tax/SSS/PHIC/Pag-IBIG can also be zeroed (unless the account is locked) | D3: Never zero D001–D004 | E3: Approved (2026-10-27)
A4: D3 | B4: Minimum net threshold | C4: Zeroing triggers below 1000; lock warning below 500 | D4: Make both a setting | E4: Approved (2026-10-27)
A5: D4 | B5: Tax method | C5: Per-period lookup in semi-monthly table, no annualization | D5: Keep for parity now; annualization is a separate feature (Alphalist/2316) | E5: Approved (2026-10-27)
A6: D5 | B6: Minimum net: how many deductions to zero | C6: LOOP in the SCAN continues instead of exiting, so every unlocked deduction is zeroed once net < 1000 | D6: Zero from highest SortDed down only until net reaches 500 (implemented) | E6: Implemented - please confirm
A8: Fill in the yellow Decision column.
